tests/32_threads/sample_94.in
32
o
6 S 104 6 1903 174
0 S 105 9 1586 193
0 C 105
9 B 108 3 1491 909
8 B 109 8 1772 343
15 B 110 4 1564 888
8 C 109
4 S 113 4 1854 852
10 B 114 0 1812 152
17 S 117 7 1027 510
10 B 118 7 1797 79
30 S 121 2 1666 938
7 S 122 6 1253 894
7 B 123 5 1745 953
10 C 114
18 B 125 5 1255 689
31 B 126 6 1012 724
7 S 127 9 1922 343
0 C 105
17 B 130 3 1243 976
3 B 131 0 1201 204
18 B 132 7 1071 705
18 C 132
7 S 135 4 1287 370
8 C 109
31 C 126
3 S 138 7 1629 932
18 C 125
20 B 140 1 1234 572
15 C 110
7 S 145 8 1845 820
6 C 104
2 B 147 5 1964 715
18 S 148 8 1239 218
31 B 149 4 1778 30
31 S 150 7 1221 142
1 B 151 7 1335 830
5 S 152 0 1338 199
8 B 154 1 1032 19
5 B 155 1 1856 506
1 B 156 6 1045 19
26 S 157 9 1237 891
6 C 104
23 B 159 4 1909 929
26 C 157
4 S 162 5 1306 445
5 C 152
17 C 117
24 B 166 6 1062 385
4 S 167 1 1301 453
10 C 118
20 B 169 6 1089 156
0 B 170 8 1679 962
10 S 171 3 1713 774
3 B 172 3 1345 187
7 S 173 7 1021 224
25 S 174 3 1905 730
14 S 175 7 1416 725
7 B 176 7 1803 424
11 S 177 0 1773 775
20 B 178 1 1221 165
19 B 180 8 1650 731
26 S 182 9 1164 256
31 B 183 7 1032 114
7 S 184 7 1108 268
13 S 185 2 1819 613
20 B 186 8 1073 643
19 C 180
6 S 188 4 1964 657
9 B 189 0 1171 317
13 B 190 3 1448 395
2 S 191 6 1205 829
19 C 180
6 S 193 5 1429 96
21 S 194 0 1561 201
29 S 195 9 1844 138
13 C 185
20 B 197 4 1675 159
27 S 198 0 1760 492
25 C 174
7 B 200 7 1572 103
13 S 202 2 1957 150
29 S 205 4 1921 799
28 B 206 2 1267 695
23 B 207 5 1349 736
30 S 208 3 1749 575
20 C 197
7 S 210 0 1783 129
19 B 211 3 1696 81
19 B 212 6 1481 328
30 S 213 6 1147 210
23 C 207
14 C 175
23 B 216 2 1300 468
5 S 217 0 1960 617
1 S 218 2 1315 520
2 C 191
28 S 220 1 1866 268
5 C 217
20 B 222 8 1144 487
4 B 223 0 1476 191
16 B 224 9 1725 923
31 C 149
4 C 167
27 C 198
0 B 228 8 1741 721
14 C 175
7 C 127
22 S 231 5 1852 695
29 S 232 6 1888 742
3 S 233 4 1650 30
2 S 234 2 1934 905
3 C 138
1 B 236 8 1380 245
20 S 237 1 1187 507
18 S 238 7 1288 995
16 S 240 0 1886 679
17 C 130
3 B 242 1 1697 437
17 C 130
1 C 236
29 S 245 9 1693 744
13 C 185
15 C 110
6 C 104
16 C 240
19 B 250 6 1260 324
12 B 251 9 1109 596
20 C 178
22 S 253 0 1876 493
14 B 254 8 1024 370
29 B 255 7 1506 367
11 S 256 4 1743 178
10 B 257 3 1359 813
18 B 258 2 1050 603
11 C 177
6 C 104
8 S 261 7 1003 724
24 B 262 6 1168 800
17 S 263 8 1245 602
19 B 264 0 1457 52
1 C 151
0 S 266 4 1243 893
26 C 157
31 B 268 0 1781 184
9 C 108
13 S 270 2 1562 483
5 S 271 5 1257 330
8 B 272 8 1108 928
31 C 149
7 S 274 2 1340 421
3 S 275 5 1375 435
26 S 276 9 1682 872
14 S 277 2 1596 670
21 B 278 6 1850 167
10 S 279 8 1717 511
6 C 188
18 B 281 2 1348 441
8 S 282 5 1483 844
21 S 283 0 1331 697
6 C 104
8 B 285 9 1141 509
4 C 113
1 C 218
15 S 288 7 1400 610
6 C 188
28 C 206
16 C 240
16 B 292 7 1605 816
13 B 293 8 1805 827
4 S 294 6 1026 295
28 C 206
2 B 296 8 1395 574
21 B 297 1 1758 796
7 S 298 3 1682 649
7 B 299 1 1265 252
26 C 182
2 B 301 2 1158 621
28 S 302 2 1182 302
6 B 303 6 1313 25
9 C 189
29 B 305 4 1140 462
28 S 306 7 1093 806
13 B 307 0 1520 100
21 S 308 0 1337 538
1 S 309 0 1612 58
28 S 310 7 1677 841
25 B 311 2 1506 560
1 B 312 2 1843 431
31 S 313 1 1202 284
30 S 314 4 1773 148
20 B 315 2 1508 430
0 C 228
21 S 317 7 1494 836
0 C 228
20 B 319 3 1230 242
21 S 320 6 1619 204
0 B 321 6 1089 885
19 C 264
16 C 240
8 C 154
6 C 188
25 B 326 3 1627 650
28 S 327 3 1725 486
22 S 328 9 1319 20
20 C 140
13 C 293
0 C 321
5 C 271
22 S 333 7 1524 263
10 B 334 8 1444 770
10 C 279
18 S 336 0 1516 482
23 C 207
7 S 338 7 1371 991
16 B 339 6 1157 542
26 S 340 5 1908 785
0 S 341 5 1279 639
26 C 182
3 C 172
19 B 344 6 1186 858
8 C 285
16 C 292
28 S 347 9 1962 201
1 S 348 6 1994 655
7 C 145
17 S 350 5 1650 738
4 C 223
18 B 352 0 1597 217
17 C 117
21 C 308
2 B 355 8 1621 753
3 S 356 6 1089 226
15 B 357 0 1369 316
6 B 358 6 1699 936
7 S 359 0 1846 281
28 S 360 9 1482 441
27 C 198
26 B 362 5 1809 803
28 S 363 2 1956 43
14 C 277
10 S 365 0 1547 780
23 C 216
3 B 367 4 1654 180
10 B 368 0 1416 1000
20 B 369 0 1702 966
15 B 370 2 1590 388
25 C 311
19 B 372 7 1552 449
22 B 373 7 1004 621
0 S 374 7 1903 353
3 B 375 7 1135 123
9 B 376 0 1892 494
20 B 377 8 1234 899
12 C 251
17 C 117
5 C 152
11 S 381 7 1915 226
24 C 166
0 C 341
7 C 338
18 S 385 2 1127 630
7 C 135
29 C 232
25 B 388 0 1330 201
16 B 389 5 1235 904
2 C 147
7 B 391 0 1034 871
23 B 392 2 1831 318
24 B 393 6 1157 997
0 C 374
25 S 395 1 1067 1000
13 B 396 3 1604 455
9 S 397 9 1341 810
3 B 398 8 1501 30
17 S 399 0 1364 721
26 S 400 2 1062 988
1 B 401 8 1297 241
2 C 234
13 C 307
29 B 404 5 1358 109
27 S 405 6 1253 104
20 S 406 2 1713 859
14 S 407 9 1481 116
17 C 117
17 S 409 6 1821 988
29 S 410 8 1427 367
8 B 411 9 1798 723
19 C 180
6 S 413 2 1546 707
13 C 293
22 B 415 5 1638 331
28 S 416 1 1537 251
11 B 417 8 1823 739
31 C 126
1 S 419 6 1634 58
25 C 388
25 B 421 1 1554 837
23 S 422 8 1179 394
22 C 415
8 C 411
15 B 425 0 1897 753
0 B 426 6 1868 507
3 S 427 7 1259 875
27 B 428 7 1891 467
6 C 303
26 S 430 7 1189 721
1 C 151
16 S 432 2 1978 751
9 B 433 3 1858 915
22 C 253
7 B 435 0 1233 876
16 S 436 0 1889 886
31 C 268
6 S 438 2 1879 711
12 C 251
1 C 236
6 C 438
11 B 442 1 1445 350
19 S 443 1 1494 955
22 S 444 9 1563 906
22 C 253
19 C 250
30 B 447 1 1037 68
29 B 448 4 1541 565
2 C 234
18 C 132
29 C 305
16 S 452 1 1917 789
16 B 453 4 1956 646
14 C 175
4 B 455 6 1956 10
8 B 456 1 1074 363
12 S 457 1 1397 269
27 B 458 8 1952 473
15 B 459 9 1672 755
6 C 104
9 C 189
31 C 126
18 B 463 4 1795 72
11 B 464 7 1969 953
22 B 465 3 1525 262
8 S 466 9 1220 663
14 S 467 2 1492 654
14 C 175
13 B 469 6 1571 87
22 S 470 6 1615 342
5 C 155
28 B 472 0 1225 303
21 C 308
18 C 281
11 C 464
31 B 476 4 1146 687
0 B 477 2 1530 768
12 B 478 3 1059 159
15 C 357
29 S 480 6 1151 650
14 S 481 4 1012 276
8 B 482 8 1131 393
8 S 483 5 1610 867
17 C 130
18 S 485 6 1598 797
23 C 392
14 B 487 3 1049 69
20 B 488 6 1357 318
13 S 489 0 1485 96
1 S 490 3 1063 582
13 B 491 0 1528 451
28 S 492 9 1920 802
3 B 493 0 1864 370
24 C 262
0 S 495 1 1083 553
28 B 496 2 1550 495
18 B 497 3 1949 623
17 B 498 1 1691 724
26 S 499 7 1107 628
4 S 500 7 1379 596
19 C 250
12 S 502 1 1211 207
6 C 438
8 S 504 7 1527 856
8 S 505 7 1734 858
26 C 499
0 C 105
19 C 211
15 C 459
29 C 232
15 C 425
19 C 212
23 B 513 3 1117 69
13 S 514 1 1048 268
1 C 151
11 B 516 5 1586 405
19 S 517 6 1777 115
14 C 467
17 C 130
0 S 520 8 1312 876
6 C 358
9 S 522 9 1310 937
3 B 523 9 1205 856
21 B 524 8 1032 346
1 C 348
24 S 526 5 1757 411
10 S 527 5 1836 303
1 B 528 4 1498 642
27 S 529 2 1296 235
23 C 513
21 B 531 4 1293 874
14 C 254
0 C 426
30 S 534 2 1228 284
21 S 535 8 1279 980
6 S 536 2 1806 624
23 B 537 0 1223 528
3 C 275
29 C 195
23 C 537
10 C 368
3 C 427
21 C 283
18 C 385
20 C 377
14 S 546 8 1457 436
27 C 428
18 S 548 5 1722 436
19 C 211
17 S 550 4 1337 326
22 B 551 2 1120 493
5 C 152
18 B 553 0 1126 986
5 B 554 8 1830 125
21 B 555 4 1349 334
20 S 556 6 1126 684
27 S 557 9 1733 843
24 S 558 7 1503 114
3 C 367
7 B 560 1 1173 495
2 B 561 7 1390 306
2 B 562 2 1220 617
18 B 563 5 1593 907
12 S 564 3 1459 219
15 C 110
3 S 566 5 1786 985
2 S 567 0 1906 105
7 C 391
22 S 569 3 1060 107
25 S 570 2 1972 71
9 S 571 6 1892 39
12 B 572 6 1068 632
22 S 573 2 1531 510
5 C 217
1 C 401
4 S 576 8 1058 770
11 S 577 5 1224 35
28 C 220
20 C 377
25 C 174
20 B 581 5 1902 189
17 S 582 1 1135 658
7 B 583 8 1527 482
26 C 276
26 S 585 0 1506 412
18 S 586 5 1644 899
3 B 587 2 1327 591
25 B 588 5 1101 487
28 S 589 9 1963 477
3 C 493
5 S 591 3 1390 795
24 C 262
17 B 593 9 1161 805
5 S 594 8 1393 227
20 B 595 5 1913 253
12 C 478
31 S 597 8 1247 33
20 S 598 0 1637 682
20 S 599 4 1240 533
25 B 600 4 1961 664
10 S 601 3 1666 23
13 S 602 9 1025 683
30 B 603 2 1720 681
31 C 149
23 S 605 7 1982 816
6 B 606 9 1819 997
25 B 607 9 1437 262
5 S 608 3 1036 942
19 B 609 5 1074 996
17 S 610 0 1584 260
19 S 611 8 1010 179
20 C 598
18 B 613 9 1890 401
0 S 614 1 1193 824
6 B 615 2 1794 919
20 S 616 2 1809 199
31 B 617 1 1897 49
4 B 618 7 1115 113
9 B 619 3 1612 943
11 C 381
28 S 621 0 1894 631
10 S 622 3 1417 213
5 C 217
2 S 624 3 1461 183
7 B 625 2 1950 994
