tests/32_threads/sample_95.in
32
o
16 B 102 0 1465 70
0 B 103 8 1400 295
26 B 105 5 1553 708
16 B 106 3 1228 829
20 B 108 3 1414 201
22 S 110 7 1643 597
25 S 111 3 1122 243
21 S 113 9 1273 968
30 B 114 4 1131 853
16 S 116 0 1214 331
21 S 118 1 1129 689
11 B 119 5 1765 175
2 S 120 7 1845 964
31 B 121 0 1447 866
13 S 123 1 1718 836
26 S 125 7 1878 193
13 C 123
27 B 128 6 1331 797
5 B 129 4 1068 870
23 S 130 8 1134 564
6 S 131 6 1705 28
28 B 132 2 2000 247
11 S 133 8 1783 216
2 S 134 8 1946 401
0 C 103
5 S 136 1 1738 541
28 S 137 1 1902 582
11 B 138 0 1063 69
12 B 139 7 1813 999
27 B 140 1 1451 230
0 B 141 9 1790 114
18 S 142 3 1399 792
24 B 143 9 1114 896
2 S 144 9 1381 53
16 C 102
16 B 146 0 1897 320
28 B 147 7 1353 858
26 C 105
29 B 149 5 1351 994
26 B 151 9 1295 688
25 B 152 7 1675 177
16 C 106
11 B 154 3 1785 666
11 C 119
27 B 158 1 1015 162
17 S 159 6 1188 525
29 C 149
16 C 102
18 C 142
15 S 165 0 1962 558
30 B 166 1 1791 816
26 B 167 1 1745 673
12 C 139
25 S 170 3 1413 65
25 B 171 4 1463 560
16 C 102
17 S 173 9 1900 442
13 C 123
11 C 138
19 S 177 1 1834 156
31 B 178 2 1940 504
10 S 179 4 1210 726
23 S 180 7 1638 86
3 S 181 8 1101 283
17 C 173
26 S 183 1 1929 446
18 C 142
25 S 185 6 1466 815
12 B 187 5 1518 87
5 S 188 0 1356 147
11 S 189 1 1888 593
12 B 190 7 1511 770
15 S 192 1 1737 457
30 B 193 5 1669 731
21 B 194 0 1675 694
19 B 195 3 1775 865
2 B 196 0 1243 765
13 C 123
29 B 198 9 1218 955
1 S 199 9 1809 798
8 S 201 5 1629 942
4 B 202 3 1712 904
31 B 203 6 1774 965
11 B 204 6 1660 76
24 B 205 7 1390 627
23 B 206 5 1290 385
22 C 110
15 C 165
29 C 198
27 B 210 4 1929 34
20 C 108
17 B 212 0 1610 968
13 B 213 4 1689 515
27 S 214 0 1397 602
20 C 108
19 C 177
18 C 142
10 B 218 0 1296 993
6 S 219 7 1044 812
27 B 220 4 1090 530
26 C 183
28 B 222 6 1624 440
4 S 223 1 1622 413
19 S 224 1 1918 701
0 C 141
12 S 226 9 1558 630
3 B 227 4 1111 403
5 S 228 3 1510 650
25 C 170
25 C 111
19 C 195
27 C 220
30 C 193
3 C 227
16 S 235 0 1423 294
9 B 236 6 1161 416
4 B 237 5 1059 205
18 C 142
23 C 130
4 S 240 8 1313 282
2 S 241 0 1907 204
6 S 242 9 1979 383
11 C 189
11 C 119
16 B 245 5 1184 859
14 B 246 5 1364 522
5 B 247 2 1392 560
20 S 248 3 1905 578
16 C 235
5 C 247
24 C 205
19 B 252 1 1372 46
0 S 253 3 1041 190
18 S 254 9 1411 462
20 S 255 1 1466 679
22 C 110
11 C 138
25 C 185
23 S 259 9 1669 892
10 S 260 5 1265 172
17 B 261 2 1646 614
9 S 262 8 1778 51
24 S 263 6 1912 490
14 B 264 3 1647 777
18 S 265 1 1158 829
6 S 266 8 1456 277
1 C 199
24 B 268 8 1584 335
31 S 269 5 1741 321
17 C 261
31 B 271 5 1882 797
9 C 236
21 B 273 7 1891 367
29 S 274 1 1057 71
2 S 275 7 1118 245
20 B 276 3 1260 466
20 B 277 9 1755 809
31 C 203
27 S 279 2 1971 527
12 C 139
20 C 248
24 B 282 6 1727 571
28 B 283 8 1290 460
30 C 193
17 B 285 2 1202 305
1 B 286 4 1172 583
3 C 227
2 S 288 4 1985 876
3 B 289 5 1564 203
16 B 290 5 1042 485
8 C 201
28 B 292 6 1293 244
18 C 142
2 B 294 3 1451 636
6 C 266
30 B 296 8 1759 271
5 B 297 6 1417 407
4 B 298 9 1271 283
19 C 252
0 B 300 9 1852 585
10 S 301 3 1755 271
18 S 302 4 1840 534
31 C 271
29 C 274
2 B 305 8 1921 969
8 C 201
31 B 307 7 1082 285
15 C 192
4 C 240
7 S 310 8 1100 663
7 B 311 9 1091 191
18 S 312 1 1395 55
29 B 313 3 1640 343
0 B 314 3 1044 700
15 C 165
12 C 226
5 S 317 4 1949 779
27 C 128
11 S 319 6 1821 588
31 S 320 9 1629 832
9 C 262
19 S 322 1 1175 555
28 B 323 8 1317 744
7 S 324 6 1325 788
20 B 325 7 1001 724
17 S 326 9 1402 441
30 S 327 7 1742 525
22 B 328 7 1023 510
14 C 264
2 S 330 0 1064 331
10 B 331 4 1315 840
7 S 332 9 1002 405
1 C 286
17 S 334 9 1053 775
12 S 335 8 1157 56
21 C 273
7 B 337 7 1859 25
3 C 289
7 B 339 7 1795 523
7 C 339
2 C 120
15 B 342 9 1865 913
16 B 343 6 1442 458
22 C 110
1 C 199
0 S 346 4 1286 798
6 S 347 9 1894 801
24 B 348 3 1665 852
25 B 349 8 1277 674
9 B 350 0 1041 533
31 B 351 5 1048 350
14 C 246
17 C 212
24 C 348
1 B 355 3 1699 602
21 S 356 9 1652 949
8 C 201
6 B 358 9 1287 264
11 S 359 3 1786 525
16 C 106
21 S 361 3 1858 576
3 S 362 8 1548 407
10 C 218
11 B 364 7 1216 498
20 S 365 3 1923 955
4 S 366 8 1335 907
23 C 180
10 B 368 3 1889 632
7 C 311
11 B 370 6 1728 236
6 B 371 2 1333 940
7 B 372 8 1938 659
6 S 373 0 1281 453
9 B 374 4 1314 296
20 S 375 9 1672 351
16 S 376 0 1582 927
20 S 377 1 1900 552
24 S 378 1 1878 113
21 C 356
16 B 380 9 1438 908
16 C 290
13 C 123
19 C 195
22 B 384 4 1177 869
1 B 385 7 1561 96
30 C 327
22 B 387 9 1310 764
17 C 173
25 C 171
24 S 390 3 1991 239
8 S 391 5 1860 178
9 S 392 2 1934 599
22 B 393 2 1341 630
24 S 394 3 1823 382
15 C 192
4 C 240
12 B 397 6 1365 532
29 B 398 7 1620 780
7 B 399 4 1101 260
22 S 400 9 1192 524
19 S 401 7 1492 902
16 C 245
6 S 403 4 1755 343
31 B 404 6 1912 750
13 C 213
15 B 406 4 1286 24
0 B 407 1 1935 930
26 B 408 1 1417 739
1 S 409 9 1924 505
10 S 410 1 1809 578
5 S 411 7 1455 823
31 C 404
18 C 142
14 S 414 0 1012 840
31 C 320
3 S 416 9 1923 916
13 S 417 8 1764 864
12 B 418 1 1189 680
11 S 419 7 1814 800
11 B 420 5 1649 897
11 B 421 5 1867 129
5 B 422 1 1782 152
28 B 423 9 1883 212
9 B 424 2 1951 734
8 B 425 3 1793 623
22 B 426 1 1758 564
14 S 427 9 1919 286
5 S 428 1 1007 298
13 C 123
18 S 430 7 1646 810
19 S 431 1 1215 773
6 S 432 1 1060 986
8 C 391
0 S 434 2 1931 485
19 S 435 6 1370 153
17 B 436 5 1452 965
13 C 213
8 S 438 1 1195 561
30 S 439 6 1659 647
19 S 440 9 1906 622
24 S 441 2 1525 953
4 S 442 5 1930 939
17 C 261
2 S 444 4 1659 403
14 B 445 9 1434 750
22 S 446 9 1122 487
28 B 447 9 1359 609
31 C 351
27 S 449 1 1867 760
30 S 450 8 1945 170
17 C 326
8 C 391
13 C 213
20 C 276
12 S 455 6 1358 55
21 S 456 7 1190 188
18 S 457 5 1304 737
5 S 458 1 1680 463
16 S 459 1 1886 710
20 C 375
15 B 461 9 1525 102
9 S 462 3 1546 366
16 C 245
22 C 393
1 B 465 9 1650 662
0 B 466 4 1312 912
18 S 467 2 1639 730
17 S 468 1 1441 695
5 S 469 8 1100 62
1 B 470 8 1454 167
31 B 471 8 1636 576
17 S 472 3 1306 444
2 C 288
10 S 474 5 1243 410
31 B 475 5 1081 615
17 S 476 0 1903 675
1 S 477 4 1995 46
5 B 478 5 1438 574
4 C 240
13 S 480 7 1280 161
18 S 481 2 1039 875
30 B 482 3 1452 456
5 S 483 4 1539 263
4 S 484 4 1882 819
25 C 111
6 B 486 8 1404 927
25 B 487 8 1288 317
10 C 368
8 B 489 3 1847 433
27 C 158
27 B 491 7 1799 86
31 C 203
19 B 493 3 1478 539
15 B 494 7 1173 418
26 S 495 3 1238 219
1 C 286
30 C 193
7 S 498 0 1618 480
1 B 499 5 1155 854
23 B 500 9 1354 986
30 B 501 1 1102 716
29 S 502 8 1442 62
1 S 503 9 1798 812
6 C 266
13 B 505 8 1468 49
0 C 434
27 S 507 8 1782 721
6 S 508 1 1624 275
17 S 509 2 1652 846
30 S 510 9 1193 951
4 S 511 2 1441 39
3 C 289
31 C 320
19 C 493
22 B 515 0 1079 762
10 B 516 1 1836 884
2 B 517 4 1081 710
18 B 518 9 1946 902
23 B 519 4 1509 699
24 C 263
4 B 521 3 1634 746
12 C 418
1 C 465
4 S 524 7 1806 994
7 S 525 1 1759 762
6 B 526 5 1080 786
30 B 527 7 1669 328
16 S 528 0 1030 322
31 C 351
22 C 400
19 C 322
9 C 462
13 S 533 1 1358 853
30 C 527
8 C 201
3 C 362
13 C 505
1 C 465
7 B 539 8 1167 256
0 C 314
12 C 335
3 C 416
27 S 543 6 1240 619
12 C 190
26 C 167
27 B 546 9 1260 742
13 B 547 9 1809 392
31 S 548 3 1471 983
28 B 549 6 1940 248
17 C 173
29 C 198
0 C 300
12 B 553 4 1634 797
11 C 204
21 B 555 3 1017 975
29 C 274
15 C 461
22 C 387
13 C 123
0 S 560 8 1111 892
31 C 404
10 S 562 3 1300 957
4 C 223
0 B 564 8 1196 154
5 C 188
4 S 566 6 1894 134
25 C 170
4 B 568 2 1228 917
11 C 119
23 B 570 5 1187 302
22 S 571 5 1588 348
30 S 572 3 1384 231
12 S 573 1 1987 947
28 S 574 4 1809 11
14 B 575 8 1603 965
14 S 576 2 1335 771
27 S 577 5 1411 703
13 C 505
1 B 579 1 1418 362
8 S 580 4 1401 412
12 S 581 8 1799 872
23 S 582 5 1215 889
23 C 582
6 C 508
25 S 585 4 1559 738
13 C 480
1 S 587 1 1346 685
16 C 343
4 B 589 7 1831 505
10 S 590 9 1984 127
27 B 591 4 1059 426
19 B 592 9 1694 596
23 B 593 6 1052 134
1 B 594 2 1615 776
1 C 385
15 B 596 8 1236 69
0 C 560
17 C 173
10 C 590
5 S 600 9 1657 556
4 C 202
20 B 602 4 1503 13
14 S 603 5 1065 477
29 S 604 8 1948 878
23 S 605 8 1212 359
30 C 450
0 S 607 3 1076 650
17 B 608 5 1718 900
8 S 609 2 1341 955
13 B 610 3 1839 771
9 B 611 2 1420 809
20 B 612 3 1239 975
25 C 585
26 C 105
12 B 615 9 1344 301
5 B 616 4 1476 476
16 C 116
8 B 618 8 1673 903
